{"uid":"bb68de9a1f98ef70","name":"test_network_cut_without_ip_change","fullName":"tests.integration.ha_tests.test_self_healing#test_network_cut_without_ip_change","historyId":"c42817a2584f9afe9bfa320de7305305","time":{"start":1718161885111,"stop":1718162067022,"duration":181911},"description":"Completely cut and restore network (situation when the unit IP doesn't change).","descriptionHtml":"<p>Completely cut and restore network (situation when the unit IP doesn't change).</p>\n","status":"broken","statusMessage":"tenacity.RetryError: RetryError[<Future at 0xf992467758a0 state=finished raised AssertionError>]","statusTrace":"Traceback (most recent call last):\n  File \"/home/runner/work/test-runners-2-github-arm64-postgresql-operator/test-runners-2-github-arm64-postgresql-operator/tests/integration/ha_tests/helpers.py\", line 634, in get_primary\n    assert action.results[\"primary\"] is not None and action.results[\"primary\"] != \"None\"\nAssertionError\n\nThe above exception was the direct cause of the following exception:\n\nTraceback (most recent call last):\n  File \"/home/runner/work/test-runners-2-github-arm64-postgresql-operator/test-runners-2-github-arm64-postgresql-operator/.tox/integration/lib/python3.10/site-packages/_pytest/runner.py\", line 341, in from_call\n    result: Optional[TResult] = func()\n  File \"/home/runner/work/test-runners-2-github-arm64-postgresql-operator/test-runners-2-github-arm64-postgresql-operator/.tox/integration/lib/python3.10/site-packages/_pytest/runner.py\", line 241, in <lambda>\n    lambda: runtest_hook(item=item, **kwds), when=when, reraise=reraise\n  File \"/home/runner/work/test-runners-2-github-arm64-postgresql-operator/test-runners-2-github-arm64-postgresql-operator/.tox/integration/lib/python3.10/site-packages/pluggy/_hooks.py\", line 513, in __call__\n    return self._hookexec(self.name, self._hookimpls.copy(), kwargs, firstresult)\n  File \"/home/runner/work/test-runners-2-github-arm64-postgresql-operator/test-runners-2-github-arm64-postgresql-operator/.tox/integration/lib/python3.10/site-packages/pluggy/_manager.py\", line 120, in _hookexec\n    return self._inner_hookexec(hook_name, methods, kwargs, firstresult)\n  File \"/home/runner/work/test-runners-2-github-arm64-postgresql-operator/test-runners-2-github-arm64-postgresql-operator/.tox/integration/lib/python3.10/site-packages/pluggy/_callers.py\", line 182, in _multicall\n    return outcome.get_result()\n  File \"/home/runner/work/test-runners-2-github-arm64-postgresql-operator/test-runners-2-github-arm64-postgresql-operator/.tox/integration/lib/python3.10/site-packages/pluggy/_result.py\", line 100, in get_result\n    raise exc.with_traceback(exc.__traceback__)\n  File \"/home/runner/work/test-runners-2-github-arm64-postgresql-operator/test-runners-2-github-arm64-postgresql-operator/.tox/integration/lib/python3.10/site-packages/pluggy/_callers.py\", line 167, in _multicall\n    teardown.throw(outcome._exception)\n  File \"/home/runner/work/test-runners-2-github-arm64-postgresql-operator/test-runners-2-github-arm64-postgresql-operator/.tox/integration/lib/python3.10/site-packages/_pytest/threadexception.py\", line 87, in pytest_runtest_call\n    yield from thread_exception_runtest_hook()\n  File \"/home/runner/work/test-runners-2-github-arm64-postgresql-operator/test-runners-2-github-arm64-postgresql-operator/.tox/integration/lib/python3.10/site-packages/_pytest/threadexception.py\", line 63, in thread_exception_runtest_hook\n    yield\n  File \"/home/runner/work/test-runners-2-github-arm64-postgresql-operator/test-runners-2-github-arm64-postgresql-operator/.tox/integration/lib/python3.10/site-packages/pluggy/_callers.py\", line 167, in _multicall\n    teardown.throw(outcome._exception)\n  File \"/home/runner/work/test-runners-2-github-arm64-postgresql-operator/test-runners-2-github-arm64-postgresql-operator/.tox/integration/lib/python3.10/site-packages/_pytest/unraisableexception.py\", line 90, in pytest_runtest_call\n    yield from unraisable_exception_runtest_hook()\n  File \"/home/runner/work/test-runners-2-github-arm64-postgresql-operator/test-runners-2-github-arm64-postgresql-operator/.tox/integration/lib/python3.10/site-packages/_pytest/unraisableexception.py\", line 65, in unraisable_exception_runtest_hook\n    yield\n  File \"/home/runner/work/test-runners-2-github-arm64-postgresql-operator/test-runners-2-github-arm64-postgresql-operator/.tox/integration/lib/python3.10/site-packages/pluggy/_callers.py\", line 167, in _multicall\n    teardown.throw(outcome._exception)\n  File \"/home/runner/work/test-runners-2-github-arm64-postgresql-operator/test-runners-2-github-arm64-postgresql-operator/.tox/integration/lib/python3.10/site-packages/_pytest/logging.py\", line 850, in pytest_runtest_call\n    yield from self._runtest_for(item, \"call\")\n  File \"/home/runner/work/test-runners-2-github-arm64-postgresql-operator/test-runners-2-github-arm64-postgresql-operator/.tox/integration/lib/python3.10/site-packages/_pytest/logging.py\", line 833, in _runtest_for\n    yield\n  File \"/home/runner/work/test-runners-2-github-arm64-postgresql-operator/test-runners-2-github-arm64-postgresql-operator/.tox/integration/lib/python3.10/site-packages/pluggy/_callers.py\", line 167, in _multicall\n    teardown.throw(outcome._exception)\n  File \"/home/runner/work/test-runners-2-github-arm64-postgresql-operator/test-runners-2-github-arm64-postgresql-operator/.tox/integration/lib/python3.10/site-packages/_pytest/capture.py\", line 878, in pytest_runtest_call\n    return (yield)\n  File \"/home/runner/work/test-runners-2-github-arm64-postgresql-operator/test-runners-2-github-arm64-postgresql-operator/.tox/integration/lib/python3.10/site-packages/pluggy/_callers.py\", line 167, in _multicall\n    teardown.throw(outcome._exception)\n  File \"/home/runner/work/test-runners-2-github-arm64-postgresql-operator/test-runners-2-github-arm64-postgresql-operator/.tox/integration/lib/python3.10/site-packages/_pytest/skipping.py\", line 257, in pytest_runtest_call\n    return (yield)\n  File \"/home/runner/work/test-runners-2-github-arm64-postgresql-operator/test-runners-2-github-arm64-postgresql-operator/.tox/integration/lib/python3.10/site-packages/pluggy/_callers.py\", line 103, in _multicall\n    res = hook_impl.function(*args)\n  File \"/home/runner/work/test-runners-2-github-arm64-postgresql-operator/test-runners-2-github-arm64-postgresql-operator/.tox/integration/lib/python3.10/site-packages/_pytest/runner.py\", line 183, in pytest_runtest_call\n    raise e\n  File \"/home/runner/work/test-runners-2-github-arm64-postgresql-operator/test-runners-2-github-arm64-postgresql-operator/.tox/integration/lib/python3.10/site-packages/_pytest/runner.py\", line 173, in pytest_runtest_call\n    item.runtest()\n  File \"/home/runner/work/test-runners-2-github-arm64-postgresql-operator/test-runners-2-github-arm64-postgresql-operator/.tox/integration/lib/python3.10/site-packages/_pytest/python.py\", line 1627, in runtest\n    self.ihook.pytest_pyfunc_call(pyfuncitem=self)\n  File \"/home/runner/work/test-runners-2-github-arm64-postgresql-operator/test-runners-2-github-arm64-postgresql-operator/.tox/integration/lib/python3.10/site-packages/pluggy/_hooks.py\", line 513, in __call__\n    return self._hookexec(self.name, self._hookimpls.copy(), kwargs, firstresult)\n  File \"/home/runner/work/test-runners-2-github-arm64-postgresql-operator/test-runners-2-github-arm64-postgresql-operator/.tox/integration/lib/python3.10/site-packages/pluggy/_manager.py\", line 120, in _hookexec\n    return self._inner_hookexec(hook_name, methods, kwargs, firstresult)\n  File \"/home/runner/work/test-runners-2-github-arm64-postgresql-operator/test-runners-2-github-arm64-postgresql-operator/.tox/integration/lib/python3.10/site-packages/pluggy/_callers.py\", line 182, in _multicall\n    return outcome.get_result()\n  File \"/home/runner/work/test-runners-2-github-arm64-postgresql-operator/test-runners-2-github-arm64-postgresql-operator/.tox/integration/lib/python3.10/site-packages/pluggy/_result.py\", line 100, in get_result\n    raise exc.with_traceback(exc.__traceback__)\n  File \"/home/runner/work/test-runners-2-github-arm64-postgresql-operator/test-runners-2-github-arm64-postgresql-operator/.tox/integration/lib/python3.10/site-packages/pluggy/_callers.py\", line 103, in _multicall\n    res = hook_impl.function(*args)\n  File \"/home/runner/work/test-runners-2-github-arm64-postgresql-operator/test-runners-2-github-arm64-postgresql-operator/.tox/integration/lib/python3.10/site-packages/_pytest/python.py\", line 162, in pytest_pyfunc_call\n    result = testfunction(**testargs)\n  File \"/home/runner/work/test-runners-2-github-arm64-postgresql-operator/test-runners-2-github-arm64-postgresql-operator/.tox/integration/lib/python3.10/site-packages/pytest_asyncio/plugin.py\", line 529, in inner\n    _loop.run_until_complete(task)\n  File \"/usr/lib/python3.10/asyncio/base_events.py\", line 649, in run_until_complete\n    return future.result()\n  File \"/home/runner/work/test-runners-2-github-arm64-postgresql-operator/test-runners-2-github-arm64-postgresql-operator/tests/integration/ha_tests/test_self_healing.py\", line 477, in test_network_cut_without_ip_change\n    primary_name = await get_primary(ops_test, app)\n  File \"/home/runner/work/test-runners-2-github-arm64-postgresql-operator/test-runners-2-github-arm64-postgresql-operator/tests/integration/ha_tests/helpers.py\", line 629, in get_primary\n    for attempt in Retrying(stop=stop_after_delay(60 * 3), wait=wait_fixed(3)):\n  File \"/home/runner/work/test-runners-2-github-arm64-postgresql-operator/test-runners-2-github-arm64-postgresql-operator/.tox/integration/lib/python3.10/site-packages/tenacity/__init__.py\", line 347, in __iter__\n    do = self.iter(retry_state=retry_state)\n  File \"/home/runner/work/test-runners-2-github-arm64-postgresql-operator/test-runners-2-github-arm64-postgresql-operator/.tox/integration/lib/python3.10/site-packages/tenacity/__init__.py\", line 326, in iter\n    raise retry_exc from fut.exception()\ntenacity.RetryError: RetryError[<Future at 0xf992467758a0 state=finished raised AssertionError>]","flaky":false,"newFailed":false,"newBroken":true,"newPassed":false,"retriesCount":1,"retriesStatusChange":true,"beforeStages":[{"name":"event_loop","time":{"start":1718157174771,"stop":1718157174771,"duration":0},"status":"passed","steps":[],"attachments":[],"parameters":[],"stepsCount":0,"shouldDisplayMessage":false,"attachmentsCount":0,"hasContent":false,"attachmentStep":false},{"name":"tmp_path_factory","time":{"start":1718157174771,"stop":1718157174771,"duration":0},"status":"passed","steps":[],"attachments":[],"parameters":[],"stepsCount":0,"shouldDisplayMessage":false,"attachmentsCount":0,"hasContent":false,"attachmentStep":false},{"name":"ops_test","time":{"start":1718157174771,"stop":1718157174987,"duration":216},"status":"passed","steps":[],"attachments":[],"parameters":[],"stepsCount":0,"shouldDisplayMessage":false,"attachmentsCount":0,"hasContent":false,"attachmentStep":false},{"name":"primary_start_timeout","time":{"start":1718158624166,"stop":1718158626251,"duration":2085},"status":"passed","steps":[],"attachments":[],"parameters":[],"stepsCount":0,"shouldDisplayMessage":false,"attachmentsCount":0,"hasContent":false,"attachmentStep":false},{"name":"abort_on_fail","time":{"start":1718161885110,"stop":1718161885111,"duration":1},"status":"passed","steps":[],"attachments":[],"parameters":[],"stepsCount":0,"shouldDisplayMessage":false,"attachmentsCount":0,"hasContent":false,"attachmentStep":false},{"name":"continuous_writes","time":{"start":1718161885111,"stop":1718161885111,"duration":0},"status":"passed","steps":[],"attachments":[],"parameters":[],"stepsCount":0,"shouldDisplayMessage":false,"attachmentsCount":0,"hasContent":false,"attachmentStep":false}],"testStage":{"description":"Completely cut and restore network (situation when the unit IP doesn't change).","status":"broken","statusMessage":"tenacity.RetryError: RetryError[<Future at 0xf992467758a0 state=finished raised AssertionError>]","statusTrace":"Traceback (most recent call last):\n  File \"/home/runner/work/test-runners-2-github-arm64-postgresql-operator/test-runners-2-github-arm64-postgresql-operator/tests/integration/ha_tests/helpers.py\", line 634, in get_primary\n    assert action.results[\"primary\"] is not None and action.results[\"primary\"] != \"None\"\nAssertionError\n\nThe above exception was the direct cause of the following exception:\n\nTraceback (most recent call last):\n  File \"/home/runner/work/test-runners-2-github-arm64-postgresql-operator/test-runners-2-github-arm64-postgresql-operator/.tox/integration/lib/python3.10/site-packages/_pytest/runner.py\", line 341, in from_call\n    result: Optional[TResult] = func()\n  File \"/home/runner/work/test-runners-2-github-arm64-postgresql-operator/test-runners-2-github-arm64-postgresql-operator/.tox/integration/lib/python3.10/site-packages/_pytest/runner.py\", line 241, in <lambda>\n    lambda: runtest_hook(item=item, **kwds), when=when, reraise=reraise\n  File \"/home/runner/work/test-runners-2-github-arm64-postgresql-operator/test-runners-2-github-arm64-postgresql-operator/.tox/integration/lib/python3.10/site-packages/pluggy/_hooks.py\", line 513, in __call__\n    return self._hookexec(self.name, self._hookimpls.copy(), kwargs, firstresult)\n  File \"/home/runner/work/test-runners-2-github-arm64-postgresql-operator/test-runners-2-github-arm64-postgresql-operator/.tox/integration/lib/python3.10/site-packages/pluggy/_manager.py\", line 120, in _hookexec\n    return self._inner_hookexec(hook_name, methods, kwargs, firstresult)\n  File \"/home/runner/work/test-runners-2-github-arm64-postgresql-operator/test-runners-2-github-arm64-postgresql-operator/.tox/integration/lib/python3.10/site-packages/pluggy/_callers.py\", line 182, in _multicall\n    return outcome.get_result()\n  File \"/home/runner/work/test-runners-2-github-arm64-postgresql-operator/test-runners-2-github-arm64-postgresql-operator/.tox/integration/lib/python3.10/site-packages/pluggy/_result.py\", line 100, in get_result\n    raise exc.with_traceback(exc.__traceback__)\n  File \"/home/runner/work/test-runners-2-github-arm64-postgresql-operator/test-runners-2-github-arm64-postgresql-operator/.tox/integration/lib/python3.10/site-packages/pluggy/_callers.py\", line 167, in _multicall\n    teardown.throw(outcome._exception)\n  File \"/home/runner/work/test-runners-2-github-arm64-postgresql-operator/test-runners-2-github-arm64-postgresql-operator/.tox/integration/lib/python3.10/site-packages/_pytest/threadexception.py\", line 87, in pytest_runtest_call\n    yield from thread_exception_runtest_hook()\n  File \"/home/runner/work/test-runners-2-github-arm64-postgresql-operator/test-runners-2-github-arm64-postgresql-operator/.tox/integration/lib/python3.10/site-packages/_pytest/threadexception.py\", line 63, in thread_exception_runtest_hook\n    yield\n  File \"/home/runner/work/test-runners-2-github-arm64-postgresql-operator/test-runners-2-github-arm64-postgresql-operator/.tox/integration/lib/python3.10/site-packages/pluggy/_callers.py\", line 167, in _multicall\n    teardown.throw(outcome._exception)\n  File \"/home/runner/work/test-runners-2-github-arm64-postgresql-operator/test-runners-2-github-arm64-postgresql-operator/.tox/integration/lib/python3.10/site-packages/_pytest/unraisableexception.py\", line 90, in pytest_runtest_call\n    yield from unraisable_exception_runtest_hook()\n  File \"/home/runner/work/test-runners-2-github-arm64-postgresql-operator/test-runners-2-github-arm64-postgresql-operator/.tox/integration/lib/python3.10/site-packages/_pytest/unraisableexception.py\", line 65, in unraisable_exception_runtest_hook\n    yield\n  File \"/home/runner/work/test-runners-2-github-arm64-postgresql-operator/test-runners-2-github-arm64-postgresql-operator/.tox/integration/lib/python3.10/site-packages/pluggy/_callers.py\", line 167, in _multicall\n    teardown.throw(outcome._exception)\n  File \"/home/runner/work/test-runners-2-github-arm64-postgresql-operator/test-runners-2-github-arm64-postgresql-operator/.tox/integration/lib/python3.10/site-packages/_pytest/logging.py\", line 850, in pytest_runtest_call\n    yield from self._runtest_for(item, \"call\")\n  File \"/home/runner/work/test-runners-2-github-arm64-postgresql-operator/test-runners-2-github-arm64-postgresql-operator/.tox/integration/lib/python3.10/site-packages/_pytest/logging.py\", line 833, in _runtest_for\n    yield\n  File \"/home/runner/work/test-runners-2-github-arm64-postgresql-operator/test-runners-2-github-arm64-postgresql-operator/.tox/integration/lib/python3.10/site-packages/pluggy/_callers.py\", line 167, in _multicall\n    teardown.throw(outcome._exception)\n  File \"/home/runner/work/test-runners-2-github-arm64-postgresql-operator/test-runners-2-github-arm64-postgresql-operator/.tox/integration/lib/python3.10/site-packages/_pytest/capture.py\", line 878, in pytest_runtest_call\n    return (yield)\n  File \"/home/runner/work/test-runners-2-github-arm64-postgresql-operator/test-runners-2-github-arm64-postgresql-operator/.tox/integration/lib/python3.10/site-packages/pluggy/_callers.py\", line 167, in _multicall\n    teardown.throw(outcome._exception)\n  File \"/home/runner/work/test-runners-2-github-arm64-postgresql-operator/test-runners-2-github-arm64-postgresql-operator/.tox/integration/lib/python3.10/site-packages/_pytest/skipping.py\", line 257, in pytest_runtest_call\n    return (yield)\n  File \"/home/runner/work/test-runners-2-github-arm64-postgresql-operator/test-runners-2-github-arm64-postgresql-operator/.tox/integration/lib/python3.10/site-packages/pluggy/_callers.py\", line 103, in _multicall\n    res = hook_impl.function(*args)\n  File \"/home/runner/work/test-runners-2-github-arm64-postgresql-operator/test-runners-2-github-arm64-postgresql-operator/.tox/integration/lib/python3.10/site-packages/_pytest/runner.py\", line 183, in pytest_runtest_call\n    raise e\n  File \"/home/runner/work/test-runners-2-github-arm64-postgresql-operator/test-runners-2-github-arm64-postgresql-operator/.tox/integration/lib/python3.10/site-packages/_pytest/runner.py\", line 173, in pytest_runtest_call\n    item.runtest()\n  File \"/home/runner/work/test-runners-2-github-arm64-postgresql-operator/test-runners-2-github-arm64-postgresql-operator/.tox/integration/lib/python3.10/site-packages/_pytest/python.py\", line 1627, in runtest\n    self.ihook.pytest_pyfunc_call(pyfuncitem=self)\n  File \"/home/runner/work/test-runners-2-github-arm64-postgresql-operator/test-runners-2-github-arm64-postgresql-operator/.tox/integration/lib/python3.10/site-packages/pluggy/_hooks.py\", line 513, in __call__\n    return self._hookexec(self.name, self._hookimpls.copy(), kwargs, firstresult)\n  File \"/home/runner/work/test-runners-2-github-arm64-postgresql-operator/test-runners-2-github-arm64-postgresql-operator/.tox/integration/lib/python3.10/site-packages/pluggy/_manager.py\", line 120, in _hookexec\n    return self._inner_hookexec(hook_name, methods, kwargs, firstresult)\n  File \"/home/runner/work/test-runners-2-github-arm64-postgresql-operator/test-runners-2-github-arm64-postgresql-operator/.tox/integration/lib/python3.10/site-packages/pluggy/_callers.py\", line 182, in _multicall\n    return outcome.get_result()\n  File \"/home/runner/work/test-runners-2-github-arm64-postgresql-operator/test-runners-2-github-arm64-postgresql-operator/.tox/integration/lib/python3.10/site-packages/pluggy/_result.py\", line 100, in get_result\n    raise exc.with_traceback(exc.__traceback__)\n  File \"/home/runner/work/test-runners-2-github-arm64-postgresql-operator/test-runners-2-github-arm64-postgresql-operator/.tox/integration/lib/python3.10/site-packages/pluggy/_callers.py\", line 103, in _multicall\n    res = hook_impl.function(*args)\n  File \"/home/runner/work/test-runners-2-github-arm64-postgresql-operator/test-runners-2-github-arm64-postgresql-operator/.tox/integration/lib/python3.10/site-packages/_pytest/python.py\", line 162, in pytest_pyfunc_call\n    result = testfunction(**testargs)\n  File \"/home/runner/work/test-runners-2-github-arm64-postgresql-operator/test-runners-2-github-arm64-postgresql-operator/.tox/integration/lib/python3.10/site-packages/pytest_asyncio/plugin.py\", line 529, in inner\n    _loop.run_until_complete(task)\n  File \"/usr/lib/python3.10/asyncio/base_events.py\", line 649, in run_until_complete\n    return future.result()\n  File \"/home/runner/work/test-runners-2-github-arm64-postgresql-operator/test-runners-2-github-arm64-postgresql-operator/tests/integration/ha_tests/test_self_healing.py\", line 477, in test_network_cut_without_ip_change\n    primary_name = await get_primary(ops_test, app)\n  File \"/home/runner/work/test-runners-2-github-arm64-postgresql-operator/test-runners-2-github-arm64-postgresql-operator/tests/integration/ha_tests/helpers.py\", line 629, in get_primary\n    for attempt in Retrying(stop=stop_after_delay(60 * 3), wait=wait_fixed(3)):\n  File \"/home/runner/work/test-runners-2-github-arm64-postgresql-operator/test-runners-2-github-arm64-postgresql-operator/.tox/integration/lib/python3.10/site-packages/tenacity/__init__.py\", line 347, in __iter__\n    do = self.iter(retry_state=retry_state)\n  File \"/home/runner/work/test-runners-2-github-arm64-postgresql-operator/test-runners-2-github-arm64-postgresql-operator/.tox/integration/lib/python3.10/site-packages/tenacity/__init__.py\", line 326, in iter\n    raise retry_exc from fut.exception()\ntenacity.RetryError: RetryError[<Future at 0xf992467758a0 state=finished raised AssertionError>]","steps":[],"attachments":[{"uid":"3fe93f9c53c61bdc","name":"log","source":"3fe93f9c53c61bdc.txt","type":"text/plain","size":255200}],"parameters":[],"stepsCount":0,"shouldDisplayMessage":true,"attachmentsCount":1,"hasContent":true,"attachmentStep":false},"afterStages":[{"name":"continuous_writes::finalizer","time":{"start":1718162067023,"stop":1718162369969,"duration":302946},"status":"failed","statusMessage":"AssertionError: Unable to clear up continuous_writes table\nassert 'False' == 'True'\n  \n  - True\n  + False\n","statusTrace":"  File \"/home/runner/work/test-runners-2-github-arm64-postgresql-operator/test-runners-2-github-arm64-postgresql-operator/.tox/integration/lib/python3.10/site-packages/allure_commons/_allure.py\", line 221, in __call__\n    return self._fixture_function(*args, **kwargs)\n  File \"/home/runner/work/test-runners-2-github-arm64-postgresql-operator/test-runners-2-github-arm64-postgresql-operator/.tox/integration/lib/python3.10/site-packages/pytest_asyncio/plugin.py\", line 300, in finalizer\n    event_loop.run_until_complete(async_finalizer())\n  File \"/usr/lib/python3.10/asyncio/base_events.py\", line 649, in run_until_complete\n    return future.result()\n  File \"/home/runner/work/test-runners-2-github-arm64-postgresql-operator/test-runners-2-github-arm64-postgresql-operator/.tox/integration/lib/python3.10/site-packages/pytest_asyncio/plugin.py\", line 292, in async_finalizer\n    await gen_obj.__anext__()\n  File \"/home/runner/work/test-runners-2-github-arm64-postgresql-operator/test-runners-2-github-arm64-postgresql-operator/tests/integration/ha_tests/conftest.py\", line 29, in continuous_writes\n    for attempt in Retrying(stop=stop_after_delay(60 * 5), wait=wait_fixed(3), reraise=True):\n  File \"/home/runner/work/test-runners-2-github-arm64-postgresql-operator/test-runners-2-github-arm64-postgresql-operator/.tox/integration/lib/python3.10/site-packages/tenacity/__init__.py\", line 347, in __iter__\n    do = self.iter(retry_state=retry_state)\n  File \"/home/runner/work/test-runners-2-github-arm64-postgresql-operator/test-runners-2-github-arm64-postgresql-operator/.tox/integration/lib/python3.10/site-packages/tenacity/__init__.py\", line 325, in iter\n    raise retry_exc.reraise()\n  File \"/home/runner/work/test-runners-2-github-arm64-postgresql-operator/test-runners-2-github-arm64-postgresql-operator/.tox/integration/lib/python3.10/site-packages/tenacity/__init__.py\", line 158, in reraise\n    raise self.last_attempt.result()\n  File \"/usr/lib/python3.10/concurrent/futures/_base.py\", line 451, in result\n    return self.__get_result()\n  File \"/usr/lib/python3.10/concurrent/futures/_base.py\", line 403, in __get_result\n    raise self._exception\n  File \"/home/runner/work/test-runners-2-github-arm64-postgresql-operator/test-runners-2-github-arm64-postgresql-operator/tests/integration/ha_tests/conftest.py\", line 37, in continuous_writes\n    assert action.results[\"result\"] == \"True\", \"Unable to clear up continuous_writes table\"\n","steps":[],"attachments":[],"parameters":[],"stepsCount":0,"shouldDisplayMessage":true,"attachmentsCount":0,"hasContent":true,"attachmentStep":false},{"name":"abort_on_fail::0","time":{"start":1718162369969,"stop":1718162369969,"duration":0},"status":"passed","steps":[],"attachments":[],"parameters":[],"stepsCount":0,"shouldDisplayMessage":false,"attachmentsCount":0,"hasContent":false,"attachmentStep":false},{"name":"primary_start_timeout::finalizer","time":{"start":1718162369970,"stop":1718162379995,"duration":10025},"status":"passed","steps":[],"attachments":[],"parameters":[],"stepsCount":0,"shouldDisplayMessage":false,"attachmentsCount":0,"hasContent":false,"attachmentStep":false},{"name":"ops_test::finalizer","time":{"start":1718162379996,"stop":1718162380453,"duration":457},"status":"passed","steps":[],"attachments":[],"parameters":[],"stepsCount":0,"shouldDisplayMessage":false,"attachmentsCount":0,"hasContent":false,"attachmentStep":false},{"name":"event_loop::2","time":{"start":1718162380454,"stop":1718162380454,"duration":0},"status":"passed","steps":[],"attachments":[],"parameters":[],"stepsCount":0,"shouldDisplayMessage":false,"attachmentsCount":0,"hasContent":false,"attachmentStep":false},{"name":"event_loop::_close_event_loop","time":{"start":1718162380454,"stop":1718162380454,"duration":0},"status":"passed","steps":[],"attachments":[],"parameters":[],"stepsCount":0,"shouldDisplayMessage":false,"attachmentsCount":0,"hasContent":false,"attachmentStep":false},{"name":"event_loop::_provide_clean_event_loop","time":{"start":1718162380454,"stop":1718162380454,"duration":0},"status":"passed","steps":[],"attachments":[],"parameters":[],"stepsCount":0,"shouldDisplayMessage":false,"attachmentsCount":0,"hasContent":false,"attachmentStep":false}],"labels":[{"name":"tag","value":"group(1)"},{"name":"tag","value":"asyncio"},{"name":"parentSuite","value":"tests.integration.ha_tests"},{"name":"suite","value":"test_self_healing"},{"name":"host","value":"runner"},{"name":"thread","value":"11161-MainThread"},{"name":"framework","value":"pytest"},{"name":"language","value":"cpython3"},{"name":"package","value":"tests.integration.ha_tests.test_self_healing"},{"name":"resultFormat","value":"allure2"}],"parameters":[],"links":[],"hidden":false,"retry":false,"extra":{"severity":"normal","retries":[{"uid":"9935b1a48c3f1c85","status":"unknown","time":{}}],"categories":[{"name":"Test defects","matchedStatuses":[],"flaky":false}],"history":{"statistic":{"failed":0,"broken":1,"skipped":0,"passed":3,"unknown":1,"total":5},"items":[{"uid":"f9063675b033b9b1","reportUrl":"../73//#testresult/f9063675b033b9b1","status":"unknown","time":{}},{"uid":"edb7dd3e60dde051","reportUrl":"../72//#testresult/edb7dd3e60dde051","status":"passed","time":{"start":1718008739045,"stop":1718008974879,"duration":235834}},{"uid":"f30c0c86bd98f325","reportUrl":"../71//#testresult/f30c0c86bd98f325","status":"passed","time":{"start":1717899994563,"stop":1717900196537,"duration":201974}},{"uid":"5b6c8dd8812acd46","reportUrl":"../70//#testresult/5b6c8dd8812acd46","status":"passed","time":{"start":1717813717369,"stop":1717813899079,"duration":181710}}]},"tags":["asyncio","group(1)"]},"source":"bb68de9a1f98ef70.json","parameterValues":[]}